Workbook

Sheet Boissons
A1: BOISSONS
A2: Produit | B2: Prix (MAD) | C2: Unité
A3: Sidi Ali 75cl | C3: Casier
A4: Oulmès 75cl | C4: Casier
A5: Sidi Ali 50cl | C5: Casier
A6: Oulmès 33cl | C6: Casier
A7: Coca Cola | C7: Casier
A8: Coca Cola Zéro | C8: Casier
A9: Sprite | C9: Casier
A10: Schweppes Tonic | C10: Casier
A11: Schweppes Citron | C11: Casier
A12: Hawaï | C12: Casier
A13: Orangina | C13: Casier
A14: San Miguel | C14: Casier
A15: Café | C15: Casier

Sheet Économat
A1: ÉCONOMAT
A2: Produit | B2: Prix (MAD) | C2: Unité
A3: Huile de table
A4: Huile friteuse
A5: Cannelloni
A6: Pouches
A7: Les gants
A8: Œufs
A9: Origan
A10: Film alimentaire
A11: Finot
A12: Farine
A13: Poudre cacao
A14: Chapelure
... A73: Moutarde à l'ancienne

Sheet Éco Pdt Italien
A1: Economa Pdt Italien
A2: Produit | B2: Prix (MAD) | C2: Unité
A3: Parmesan
A4: Gorgonzola
A5: Mascarpone
A6: Brésaola
A7: Tomate pizza
A8: Riz arborio
A9: Spaghetti
A10: Linguini
A11: Penne
A12: Rigatoni
A13: Farine KENZ

Sheet Fournisseurs
A1: FOURNISSEURS
A2: Nom Complet | B2: Catégorie | C2: Numéro de Téléphone
A3: ELK Fresh | B3: Légumes | C3: +212660553784
A4: Zineb Food | B4: Légumes | C4: +212631118376
A5: Goh Negoce | B5: Économat | C5: +212661865083
A6: Hero Food | B6: Économat | C6: +212668629564
A7: Gastro Mix | B7: Fromage | C7: +212666670021
A8: Outa Bount ( Marche Central ) | B8: Fromage | C8: +212693076036
A9: Pesca Frigo | B9: Poisson | C9: +212668468936
A10: Hafsa Samak | B10: Poisson | C10: +212700082300
A11: Boucherie Anfal | B11: Viande | C11: +212670925407
A12: Moulay Said | B12: Viande | C12: +212663640400
A13: Lazzaro | B13: Économat Pdt Italien
A14: Youssef ( Marche Maarif ) | B14: Économat Pdt Italien

Sheet Fromage
A1: FROMAGE
A2: Produit | B2: Prix (MAD) | C2: Unité
A3: Burrata
A4: Ricotta
A5: Scarmosa
A6: Mozza salade
A7: Mozzarella

Sheet Légumes
A1: LÉGUMES
A2: Produit | B2: Prix (MAD) | C2: Unité
A3: Tomate
A4: Tomate cerise
A5: Tomate cerise jaune
A6: Germe
A7: Haricots verts
A8: Brocolis
A9: Petit pois
A10: Choux Bruxelles
A11: Asperges
A12: Pomme de terre
A13: Pomme nouvelle
A14: Ail
... A50: Citron

Sheet Poisson
A1: POISSON
A2: Produit | B2: Prix (MAD) | C2: Unité
A3: Calamars
A4: Moule décortiquée
A5: Moule avec coquille
A6: Chair de crabe
A7: Palourde
A8: Saumon frais
A9: Saumon fumé
A10: Poulpe
A11: Gambas 30/50
A12: Espadon
A13: Saint-Pierre

Sheet Viande
A1: VIANDE
A2: Produit | B2: Prix (MAD) | C2: Unité
A3: Blanc de poulet
A4: Filet de boeuf
A5: Entrecôte
A6: Carpaccio
A7: Viande hachée

Sheet INV-Légumes
A1: LÉGUMES
A2: Produit | B2: Prix (MAD) | C2: Unité
A3: Tomate
A4: Tomate cerise
A5: Tomate cerise jaune
A6: Germe
A7: Haricots verts
A8: Brocolis
A9: Petit pois
A10: Choux Bruxelles
A11: Asperges
A12: Pomme de terre
A13: Pomme nouvelle
A14: Ail
... A50: Citron

Sheet Suivi Journalier
A1: 🍽 SUIVI FINANCIER JOURNALIER — RESTAURANT
A2: Tableau de bord — April 2026
A4: DATE | B4: RECETTES | F4: DÉPENSES | M4: RETRAITS CARTE | R4: SOLDE THÉORIQUE | S4: OBSERVATIONS
A5: Date | B5: Recette Carte (Z Caisse) | C5: Recette Espèces (Z Caisse) | D5: Virement & Ticket Restau | E5: Total Recettes (AUTO) | F5: Dépenses Caisse (Espèces) | G5: Description | H5: Dépenses Carte (Pro) | I5: Description | J5: Dépenses TPE | K5: Description | L5: Total Dépenses (AUTO) | M5: Retraits Carte (Pro) | N5: Description | O5: Retraits Carte (Perso) | P5: Description | Q5: Retraits Carte (Total) (AUTO) | R5: Solde Théorique (AUTO) | S5: Observations
A6: 46114 | B6: 4580 | C6: 4060 | E6: =SUM(B6:D6) -> 8640 | F6: 2040.88 | L6: =F6+H6+J6 -> 2040.88 | O6: 2000 | Q6: =M6+O6 -> 2000 | R6: =E6-(L6+Q6) -> 4599.12
A7: 46115 | B7: 6655 | C7: 3710 | D7: 3455 | E7: =SUM(B7:D7) -> 13820 | F7: 2945 | L7: =F7+H7+J7 -> 2945 | O7: 2000 | Q7: =M7+O7 -> 2000 | R7: =E7-(L7+Q7) -> 8875
A8: 46116 | B8: 3310 | C8: 2565 | E8: =SUM(B8:D8) -> 5875 | F8: 4195.63 | L8: =F8+H8+J8 -> 4195.63 | M8: 2600 | O8: 400 | Q8: =M8+O8 -> 3000 | R8: =E8-(L8+Q8) -> -1320.63
A9: 46117 | B9: 4305 | C9: 1300 | E9: =SUM(B9:D9) -> 5605 | F9: 1175.5 | L9: =F9+H9+J9 -> 1175.5 | Q9: =M9+O9 -> 0 | R9: =E9-(L9+Q9) -> 4429.5
A10: 46118 | B10: 6876.5 | C10: 3608 | D10: 600 | E10: =SUM(B10:D10) -> 11084.5 | F10: 3523.25 | J10: 778.7 | K10: Marjane | L10: =F10+H10+J10 -> 4301.95 | M10: 5500 | N10: ancien bon fournisseur | O10: 500 | Q10: =M10+O10 -> 6000 | R10: =E10-(L10+Q10) -> 782.55
A11: 46119 | B11: 4140 | C11: 1920 | D11: 210 | E11: =SUM(B11:D11) -> 6270 | F11: 2604.74 | L11: =F11+H11+J11 -> 2604.74 | Q11: =M11+O11 -> 0 | R11: =E11-(L11+Q11) -> 3665.26
A12: 46120 | B12: 4335 | C12: 4335 | E12: =SUM(B12:D12) -> 8670 | F12: 1234 | H12: 1342 | I12: Nicola (vin&bierres) | L12: =F12+H12+J12 -> 2576 | Q12: =M12+O12 -> 0 | R12: =E12-(L12+Q12) -> 6094
A13: 46121 | B13: 5540 | C13: 2006.5 | E13: =SUM(B13:D13) -> 7546.5 | F13: 4727.05 | L13: =F13+H13+J13 -> 4727.05 | M13: 3500 | N13: ancien bons fournisseur 2/6 | O13: 1500 | Q13: =M13+O13 -> 5000 | R13: =E13-(L13+Q13) -> -2180.55
A14: 46122 | B14: 4830 | C14: 3043 | E14: =SUM(B14:D14) -> 7873 | F14: 1106 | L14: =F14+H14+J14 -> 1106 | Q14: =M14+O14 -> 0 | R14: =E14-(L14+Q14) -> 6767
A15: 46123 | B15: 3014 | C15: 1726 | E15: =SUM(B15:D15) -> 4740 | F15: 1938 | L15: =F15+H15+J15 -> 1938 | Q15: =M15+O15 -> 0 | R15: =E15-(L15+Q15) -> 2802
A16: 46124 | B16: 5750 | C16: 2426 | E16: =SUM(B16:D16) -> 8176 | F16: 611.3 | K16: maison | L16: =F16+H16+J16 -> 611.3 | M16: 1500 | N16: paiement ibrahima (gardien) | O16: 2500 | Q16: =M16+O16 -> 4000 | R16: =E16-(L16+Q16) -> 3564.7
A17: 46125 | B17: 4520 | C17: 1415 | E17: =SUM(B17:D17) -> 5935 | F17: 2591.07 | L17: =F17+H17+J17 -> 2591.07 | Q17: =M17+O17 -> 0 | R17: =E17-(L17+Q17) -> 3343.93
A18: 46126 | B18: 2690 | C18: 1570 | E18: =SUM(B18:D18) -> 4260 | F18: 1924.2 | L18: =F18+H18+J18 -> 1924.2 | Q18: =M18+O18 -> 0 | R18: =E18-(L18+Q18) -> 2335.8
A19: 46127 | B19: 4290 | C19: 3745 | E19: =SUM(B19:D19) -> 8035 | F19: 2237.02 | L19: =F19+H19+J19 -> 2237.02 | Q19: =M19+O19 -> 0 | R19: =E19-(L19+Q19) -> 5797.98
A20: 46128 | B20: 4240 | C20: 2785 | E20: =SUM(B20:D20) -> 7025 | F20: 2622.37 | L20: =F20+H20+J20 -> 2622.37 | Q20: =M20+O20 -> 0 | R20: =E20-(L20+Q20) -> 4402.63
A21: 46129 | B21: 4080 | C21: 2837 | E21: =SUM(B21:D21) -> 6917 | F21: 3047 | L21: =F21+H21+J21 -> 3047 | Q21: =M21+O21 -> 0 | R21: =E21-(L21+Q21) -> 3870
A22: 46130 | B22: 1845 | C22: 931 | E22: =SUM(B22:D22) -> 2776 | F22: 1792.57 | L22: =F22+H22+J22 -> 1792.57 | Q22: =M22+O22 -> 0 | R22: =E22-(L22+Q22) -> 983.43
A23: 46131 | B23: 535 | C23: 4306 | E23: =SUM(B23:D23) -> 4841 | F23: 432.5 | L23: =F23+H23+J23 -> 432.5 | Q23: =M23+O23 -> 0 | R23: =E23-(L23+Q23) -> 4408.5
A24: 46132 | B24: 4025 | C24: 2500 | E24: =SUM(B24:D24) -> 6525 | F24: 5791.5 | L24: =F24+H24+J24 -> 5791.5 | Q24: =M24+O24 -> 0 | R24: =E24-(L24+Q24) -> 733.5
A25: 46133 | B25: 5320 | C25: 1496 | E25: =SUM(B25:D25) -> 6816 | F25: 1144 | L25: =F25+H25+J25 -> 1144 | Q25: =M25+O25 -> 0 | R25: =E25-(L25+Q25) -> 5672
A26: 46134 | B26: 545 | C26: 5265 | E26: =SUM(B26:D26) -> 5810 | F26: 2191.78 | L26: =F26+H26+J26 -> 2191.78 | Q26: =M26+O26 -> 0 | R26: =E26-(L26+Q26) -> 3618.22
A27: 46135 | B27: 1930 | C27: 5360 | E27: =SUM(B27:D27) -> 7290 | F27: 5364.14 | L27: =F27+H27+J27 -> 5364.14 | Q27: =M27+O27 -> 0 | R27: =E27-(L27+Q27) -> 1925.86
A28: 43945 | B28: 1735.5 | C28: 6770 | E28: =SUM(B28:D28) -> 8505.5 | F28: 2344.5 | L28: =F28+H28+J28 -> 2344.5 | Q28: =M28+O28 -> 0 | R28: =E28-(L28+Q28) -> 6161
A29: 46137 | B29: 3775 | C29: 2845 | E29: =SUM(B29:D29) -> 6620 | F29: 3448 | L29: =F29+H29+J29 -> 3448 | Q29: =M29+O29 -> 0 | R29: =E29-(L29+Q29) -> 3172
E30: =SUM(B30:D30) -> 0 | L30: =F30+H30+J30 -> 0 | Q30: =M30+O30 -> 0 | R30: =E30-(L30+Q30) -> 0
E31: =SUM(B31:D31) -> 0 | L31: =F31+H31+J31 -> 0 | Q31: =M31+O31 -> 0 | R31: =E31-(L31+Q31) -> 0
E32: =SUM(B32:D32) -> 0 | L32: =F32+H32+J32 -> 0 | Q32: =M32+O32 -> 0 | R32: =E32-(L32+Q32) -> 0
E33: =SUM(B33:D33) -> 0 | L33: =F33+H33+J33 -> 0 | Q33: =M33+O33 -> 0 | R33: =E33-(L33+Q33) -> 0
E34: =SUM(B34:D34) -> 0 | L34: =F34+H34+J34 -> 0 | Q34: =M34+O34 -> 0 | R34: =E34-(L34+Q34) -> 0
E35: =SUM(B35:D35) -> 0 | L35: =F35+H35+J35 -> 0 | Q35: =M35+O35 -> 0 | R35: =E35-(L35+Q35) -> 0
E36: =SUM(B36:D36) -> 0 | L36: =F36+H36+J36 -> 0 | Q36: =M36+O36 -> 0 | R36: =E36-(L36+Q36) -> 0
A37: TOTAUX MENSUELS | B37: =SUM(B6:B36) -> 92866 | C37: =SUM(C6:C36) -> 72524.5 | D37: =SUM(D6:D36) -> 4265 | E37: =SUM(E6:E36) -> 169655.5 | F37: =SUM(F6:F36) -> 61032 | H37: =SUM(H6:H36) -> 1342 | J37: =SUM(J6:J36) -> 778.7 | L37: =SUM(L6:L36) -> 63152.7 | M37: =SUM(M6:M36) -> 13100 | O37: =SUM(O6:O36) -> 8900 | Q37: =SUM(Q6:Q36) -> 22000 | R37: =SUM(R6:R36) -> 84502.8

Sheet INV-Économat
A1: ÉCONOMAT
A2: Produit | B2: Prix (MAD) | C2: Unité
A3: Huile de table | C3: L
A4: Huile friteuse
A5: Cannelloni | C5: Paquet
A6: Pouches
A7: Les gants
A8: Œufs
A9: Origan
A10: Film alimentaire
A11: Finot | C11: Kg
A12: Farine | C12: Kg
A13: Poudre cacao | C13: Sachet
A14: Chapelure
A15: Thé
A16: Sucre thé
A17: Sucre semoule | C17: Kg
A18: Vinaigre blanc | C18: Bouteille
A19: Œufs (caille)
A20: Anchoix mariné
A21: Anchoix salé
A22: Boudoirs
A23: Farine capoto
A24: Farine pizza kenz | C24: Kg
A25: Charlotte
A26: Sel de table | C26: Paquet
A27: Thon | C27: Boîte
A28: Maïs | C28: Boîte
A29: Câpre | C29: Boîte
A30: Poivre vert
A31: Tomate pelée
A32: Artichaut
A33: Sac congélation
A34: Moutarde | C34: Kg
A35: Ketchup | C35: Kg
A36: Gélatine
A37: Sucre vanille
A38: Levure chimique | C38: Sachet
A39: Arôme vanille | C39: Sachet
A40: Sucre glace
...

Sheet INV-Fromage
A1: FROMAGE
A2: Produit | B2: Prix (MAD) | C2: Unité
A3: Burrata
A4: Ricotta
A5: Scarmosa
A6: Mozza salade
A7: Mozzarella

Sheet INV-Poisson
A1: POISSON
A2: Produit | B2: Prix (MAD) | C2: Unité
A3: Calamars
A4: Moule décortiquée
A5: Moule avec coquille
A6: Chair de crabe
A7: Palourde
A8: Saumon frais
A9: Saumon fumé
A10: Poulpe
A11: Gambas 30/50
A12: Espadon
A13: Saint-Pierre

Sheet INV-Viande
A1: VIANDE
A2: Produit | B2: Prix (MAD) | C2: Unité
A3: Blanc de poulet
A4: Filet de boeuf
A5: Entrecôte
A6: Carpaccio
A7: Viande hachée

Sheet INV-Éco Pdt Italien
A1: ÉCONOMAT PDT ITALIEN
A2: Produit | B2: Prix (MAD) | C2: Unité
A3: Parmesan
A4: Gorgonzola
A5: Mascarpone
A6: Brésaola
A7: Tomate pizza
A8: Riz arborio | C8: Kg
A9: Spaghetti | C9: Kg
A10: Linguini | C10: Paquet
A11: Penne | C11: Kg
A12: Rigatoni | C12: Paquet
A13: Farine KENZ | C13: Kg
A14: Penne ziti rigate | C14: Paquet
A15: Nouilles soba | C15: Paquet
A16: Riz noir | C16: Paquet
A17: Tartufata | C17: Boîte
A18: Tartufo nero | C18: Bouteille

Sheet INV-Fournisseurs
A1: FOURNISSEURS
A2: Nom Complet | B2: Catégorie | C2: Numéro de Téléphone
A3: ELK Fresh | B3: Légumes | C3: +212660553784
A4: Zineb Food | B4: Légumes | C4: +212631118376
A5: Goh Negoce | B5: Économat | C5: +212661865083
A6: Hero Food | B6: Économat | C6: +212668629564
A7: Gastro Mix | B7: Fromage | C7: +212666670021
A8: Outa Bount ( Marche Central ) | B8: Fromage | C8: +212693076036
A9: Pesca Frigo | B9: Poisson | C9: +212668468936
A10: Hafsa Samak | B10: Poisson | C10: +212700082300
A11: Boucherie Anfal | B11: Viande | C11: +212670925407
A12: Moulay Said | B12: Viande | C12: +212663640400
A13: Lazzaro | B13: Économat Pdt Italien
A14: Youssef ( Marche Maarif ) | B14: Économat Pdt Italien

Sheet INV-Boissons
A1: BOISSONS
A2: Produit | B2: Prix (MAD) | C2: Unité
A3: Sidi Ali 75cl | C3: Casier
A4: Oulmès 75cl | C4: Casier
A5: Sidi Ali 50cl | C5: Casier
A6: Oulmès 33cl | C6: Casier
A7: Coca Cola | C7: Casier
A8: Coca Cola Zéro | C8: Casier
A9: Sprite | C9: Casier
A10: Schweppes Tonic | C10: Casier
A11: Schweppes Citron | C11: Casier
A12: Hawaï | C12: Casier
A13: Orangina | C13: Casier
A14: San Miguel | C14: Casier
A15: Café | C15: Casier

Sheet Legende
A1: LEGENDE DES COULEURS ET INSTRUCTIONS
A3: COULEURS DES CELLULES
A4: Texte bleu | B4: Saisie manuelle (donnees a entrer par l'utilisateur)
A5: Texte noir gras | B5: Calcul automatique (ne pas modifier)
A7: COLONNES - DEFINITIONS
A8: Date | B8: Date du jour (format JJ/MM/AAAA)
A9: Recette Carte | B9: Montant des recettes carte bancaire selon le Z de caisse
A10: Recette Especes | B10: Montant des recettes especes selon le Z de caisse
A11: Virement & Ticket Restau | B11: Montant des virements et tickets restaurant recus
A12: Total Recettes | B12: Recette Carte + Recette Especes (calcul automatique)
A13: Depenses Caisse | B13: Depenses reglees en especes, issues de la feuille du manager
A14: Depenses Carte (Pro) | B14: Depenses professionnelles du restaurant reglees par carte
A15: Depenses TPE | B15: Depenses reglees via le terminal de paiement electronique (TPE)
A16: Total Depenses | B16: Depenses Caisse + Depenses Carte Pro + Depenses TPE (calcul automatique)
A17: Retraits Carte (Pro) | B17: Retraits effectues pour les besoins du restaurant
A18: Retraits Carte (Perso) | B18: Retraits personnels effectues avec la carte du restaurant
A19: Total Retraits | B19: Retraits Pro + Retraits Perso (calcul automatique)
A21: INSTRUCTIONS D'UTILISATION
A22: 1 | B22: Remplir quotidiennement les cellules en bleu
A23: 2 | B23: Ne jamais modifier les cellules en noir gras (formules automatiques)
A24: 3 | B24: Le Solde Theorique = Total Recettes - (Total Depenses + Total Retraits)
A25: 4 | B25: Utiliser la colonne Observations pour noter tout evenement particulier
A26: 5 | B26: Verifier chaque jour que le solde theorique correspond a la realite
A27: 6 | B27: L'onglet Recap Mensuel se met a jour automatiquement
A28: 7 | B28: Conserver les Z de caisse comme justificatifs

Sheet Recap Mensuel
A1: RECAPITULATIF MENSUEL
A2: Indicateur | B2: Montant (MAD) | C2: % du Total Recettes
A3: Total Recettes Carte | B3: ='Suivi Journalier'!B37 -> 92866 | C3: =IFERROR(B3/B7,"-") -> #ERROR!
A4: Total Recettes Especes | B4: ='Suivi Journalier'!C37 -> 72524.5 | C4: =IFERROR(B4/B7,"-") -> #ERROR!
A5: Total Virement & Ticket Restau | B5: ='Suivi Journalier'!D37 -> 4265 | C5: =IFERROR(B5/B7,"-") -> #ERROR!
A7: TOTAL RECETTES | B7: ='Suivi Journalier'!E37 -> 169655.5 | C7: 1
A8: Total Depenses Caisse | B8: ='Suivi Journalier'!F37 -> 61032 | C8: =IFERROR(B8/B7,"-") -> #ERROR!
A9: Total Depenses Carte Pro | B9: ='Suivi Journalier'!H37 -> 1342 | C9: =IFERROR(B9/B7,"-") -> #ERROR!
A10: Total Depenses TPE | B10: ='Suivi Journalier'!J37 -> 778.7 | C10: =IFERROR(B10/B7,"-") -> #ERROR!
A11: TOTAL DEPENSES | B11: ='Suivi Journalier'!L37 -> 63152.7 | C11: =IFERROR(B11/B7,"-") -> #ERROR!
A12: Total Retraits Pro | B12: ='Suivi Journalier'!M37 -> 13100 | C12: =IFERROR(B12/B7,"-") -> #ERROR!
A13: Total Retraits Perso | B13: ='Suivi Journalier'!O37 -> 8900 | C13: =IFERROR(B13/B7,"-") -> #ERROR!
A14: TOTAL RETRAITS | B14: ='Suivi Journalier'!Q37 -> 22000 | C14: =IFERROR(B14/B7,"-") -> #ERROR!
A15: SOLDE THEORIQUE MENSUEL | B15: ='Suivi Journalier'!R37 -> 84502.8 | C15: =IFERROR(B15/B7,"-") -> #ERROR!

Sheet SI-Légumes
A1: LÉGUMES
A2: Produit | B2: Prix (MAD) | C2: Quantité | D2: Unité
A3: Tomate
A4: Tomate cerise
A5: Tomate cerise jaune
A6: Germe
A7: Haricots verts
A8: Brocolis
A9: Petit pois
A10: Choux Bruxelles
A11: Asperges
A12: Pomme de terre
A13: Pomme nouvelle
A14: Ail
... A50: Citron

Sheet SI-Économat
A1: ÉCONOMAT
A2: Produit | B2: Prix (MAD) | C2: Quantité | D2: Unité
A3: Huile de table | C3: 3 | D3: L
A4: Huile friteuse
A5: Cannelloni | C5: 1 | D5: Paquet
A6: Pouches
A7: Les gants
A8: Œufs
A9: Origan
A10: Film alimentaire
A11: Finot | D11: Kg
A12: Farine | D12: Kg
A13: Poudre cacao | D13: Sachet
A14: Chapelure
A15: Thé
A16: Sucre thé
A17: Sucre semoule | D17: Kg
A18: Vinaigre blanc | C18: 1 | D18: Bouteille
A19: Œufs (caille)
A20: Anchoix mariné
A21: Anchoix salé
A22: Boudoirs
A23: Farine capoto
A24: Farine pizza kenz | D24: Kg
A25: Charlotte
A26: Sel de table | D26: Paquet
A27: Thon | C27: 3 | D27: Boîte
A28: Maïs | C28: 1 | D28: Boîte
A29: Câpre | C29: 2 | D29: Boîte
A30: Poivre vert
A31: Tomate pelée
A32: Artichaut
A33: Sac congélation
A34: Moutarde | D34: Kg
A35: Ketchup | D35: Kg
A36: Gélatine
A37: Sucre vanille
A38: Levure chimique | D38: Sachet
A39: Arôme vanille | D39: Sachet
A40: Sucre glace
...

Sheet SI-Fromage
A1: FROMAGE
A2: Produit | B2: Prix (MAD) | C2: Quantité | D2: Unité
A3: Burrata
A4: Ricotta
A5: Scarmosa
A6: Mozza salade
A7: Mozzarella

Sheet SI-Poisson
A1: POISSON
A2: Produit | B2: Prix (MAD) | C2: Quantité | D2: Unité
A3: Calamars
A4: Moule décortiquée
A5: Moule avec coquille
A6: Chair de crabe
A7: Palourde
A8: Saumon frais
A9: Saumon fumé
A10: Poulpe
A11: Gambas 30/50
A12: Espadon
A13: Saint-Pierre

Sheet SI-Viande
A1: VIANDE
A2: Produit | B2: Prix (MAD) | C2: Quantité | D2: Unité
A3: Blanc de poulet
A4: Filet de boeuf
A5: Entrecôte
A6: Carpaccio
A7: Viande hachée

Sheet SI-Éco Pdt Italien
A1: ÉCONOMAT PDT ITALIEN
A2: Produit | B2: Prix (MAD) | C2: Quantité | D2: Unité
A3: Parmesan
A4: Gorgonzola
A5: Mascarpone
A6: Brésaola
A7: Tomate pizza
A8: Riz arborio | D8: Kg
A9: Spaghetti | D9: Kg
A10: Linguini | D10: Paquet
A11: Penne | D11: Kg
A12: Rigatoni | D12: Paquet
A13: Farine KENZ | D13: Kg
A14: Penne ziti rigate | D14: Paquet
A15: Nouilles soba | D15: Paquet
A16: Riz noir | D16: Paquet
A17: Tartufata | D17: Boîte
A18: Tartufo nero | D18: Bouteille

Sheet SI-Fournisseurs
A1: FOURNISSEURS
A2: Catégorie | B2: Nom Complet | C2: Numéro de Téléphone | D2: Payé (MAD) | E2: Crédit (MAD)
A3: Légumes | B3: ELK Fresh | C3: +212660553784
A4: Légumes | B4: Zineb Food | C4: +212631118376
A5: Économat | B5: Goh Negoce | C5: +212661865083
A6: Économat | B6: Hero Food | C6: +212668629564
A7: Fromage | B7: Gastro Mix | C7: +212666670021
A8: Fromage | B8: Outa Bount ( Marche Central ) | C8: +212693076036
A9: Poisson | B9: Pesca Frigo | C9: +212668468936
A10: Poisson | B10: Hafsa Samak | C10: +212700082300
A11: Viande | B11: Boucherie Anfal | C11: +212670925407
A12: Viande | B12: Moulay Said | C12: +212663640400
A13: Économat Pdt Italien | B13: Lazzaro
A14: Économat Pdt Italien | B14: Youssef ( Marche Maarif )

Sheet SI-Boissons
A1: BOISSONS
A2: Produit | B2: Prix (MAD) | C2: Quantité | D2: Unité
A3: Sidi Ali 75cl | D3: Casier
A4: Oulmès 75cl | D4: Casier
A5: Sidi Ali 50cl | D5: Casier
A6: Oulmès 33cl | D6: Casier
A7: Coca Cola | D7: Casier
A8: Coca Cola Zéro | D8: Casier
A9: Sprite | D9: Casier
A10: Schweppes Tonic | D10: Casier
A11: Schweppes Citron | D11: Casier
A12: Hawaï | D12: Casier
A13: Orangina | D13: Casier
A14: San Miguel | D14: Casier
A15: Café | D15: Casier
